[2023-10-31T22:34:57.393+0100] {taskinstance.py:1159} INFO - Dependencies all met for dep_context=non-requeueable deps ti=<TaskInstance: la_test.merge_user_principal_name_list manual__2023-10-31T16:36:16.370874+00:00 [queued]>
[2023-10-31T22:34:57.396+0100] {taskinstance.py:1159} INFO - Dependencies all met for dep_context=requeueable deps ti=<TaskInstance: la_test.merge_user_principal_name_list manual__2023-10-31T16:36:16.370874+00:00 [queued]>
[2023-10-31T22:34:57.396+0100] {taskinstance.py:1361} INFO - Starting attempt 1 of 1
[2023-10-31T22:34:57.400+0100] {taskinstance.py:1382} INFO - Executing <Task(PythonOperator): merge_user_principal_name_list> on 2023-10-31 16:36:16.370874+00:00
[2023-10-31T22:34:57.403+0100] {standard_task_runner.py:57} INFO - Started process 65592 to run task
[2023-10-31T22:34:57.406+0100] {standard_task_runner.py:84} INFO - Running: ['airflow', 'tasks', 'run', 'la_test', 'merge_user_principal_name_list', 'manual__2023-10-31T16:36:16.370874+00:00', '--job-id', '38', '--raw', '--subdir', 'DAGS_FOLDER/test_aj.py', '--cfg-path', '/var/folders/4w/73_t653s0rz1z847_g217g2h0000gn/T/tmptoujy_2u']
[2023-10-31T22:34:57.406+0100] {standard_task_runner.py:85} INFO - Job 38: Subtask merge_user_principal_name_list
[2023-10-31T22:34:57.429+0100] {task_command.py:416} INFO - Running <TaskInstance: la_test.merge_user_principal_name_list manual__2023-10-31T16:36:16.370874+00:00 [running]> on host mbp21-14
[2023-10-31T22:34:57.450+0100] {taskinstance.py:1662} INFO - Exporting env vars: AIRFLOW_CTX_DAG_OWNER='airflow' AIRFLOW_CTX_DAG_ID='la_test' AIRFLOW_CTX_TASK_ID='merge_user_principal_name_list' AIRFLOW_CTX_EXECUTION_DATE='2023-10-31T16:36:16.370874+00:00' AIRFLOW_CTX_TRY_NUMBER='1' AIRFLOW_CTX_DAG_RUN_ID='manual__2023-10-31T16:36:16.370874+00:00'
[2023-10-31T22:34:57.451+0100] {logging_mixin.py:151} INFO - []
[2023-10-31T22:34:57.451+0100] {taskinstance.py:1937} ERROR - Task failed with exception
Traceback (most recent call last):
  File "/Users/nick/miniforge3/envs/airflow_env/lib/python3.9/site-packages/airflow/operators/python.py", line 192, in execute
    return_value = self.execute_callable()
  File "/Users/nick/miniforge3/envs/airflow_env/lib/python3.9/site-packages/airflow/operators/python.py", line 209, in execute_callable
    return self.python_callable(*self.op_args, **self.op_kwargs)
  File "/Users/nick/airflow/dags/operators/transform_operators.py", line 91, in merge_dataframes_from_directory
    df = pd.concat(frames, ignore_index=True)
  File "/Users/nick/miniforge3/envs/airflow_env/lib/python3.9/site-packages/pandas/core/reshape/concat.py", line 380, in concat
    op = _Concatenator(
  File "/Users/nick/miniforge3/envs/airflow_env/lib/python3.9/site-packages/pandas/core/reshape/concat.py", line 443, in __init__
    objs, keys = self._clean_keys_and_objs(objs, keys)
  File "/Users/nick/miniforge3/envs/airflow_env/lib/python3.9/site-packages/pandas/core/reshape/concat.py", line 505, in _clean_keys_and_objs
    raise ValueError("No objects to concatenate")
ValueError: No objects to concatenate
[2023-10-31T22:34:57.453+0100] {taskinstance.py:1400} INFO - Marking task as FAILED. dag_id=la_test, task_id=merge_user_principal_name_list, execution_date=20231031T163616, start_date=20231031T213457, end_date=20231031T213457
[2023-10-31T22:34:57.457+0100] {standard_task_runner.py:104} ERROR - Failed to execute job 38 for task merge_user_principal_name_list (No objects to concatenate; 65592)
[2023-10-31T22:34:57.464+0100] {local_task_job_runner.py:228} INFO - Task exited with return code 1
[2023-10-31T22:34:57.475+0100] {taskinstance.py:2778} INFO - 0 downstream tasks scheduled from follow-on schedule check
